2018-10-07 16:05:33,128 (MainProcess pid:278364) line-1761  flask.app <log_exception> - [ERROR] : Exception on /proxy/anony/10 [GET]
Traceback (most recent call last):
  File "C:\Users\linkin\AppData\Local\Programs\Python\Python37\lib\site-packages\flask\app.py", line 2292, in wsgi_app
    response = self.full_dispatch_request()
  File "C:\Users\linkin\AppData\Local\Programs\Python\Python37\lib\site-packages\flask\app.py", line 1815, in full_dispatch_request
    rv = self.handle_user_exception(e)
  File "C:\Users\linkin\AppData\Local\Programs\Python\Python37\lib\site-packages\flask\app.py", line 1718, in handle_user_exception
    reraise(exc_type, exc_value, tb)
  File "C:\Users\linkin\AppData\Local\Programs\Python\Python37\lib\site-packages\flask\_compat.py", line 35, in reraise
    raise value
  File "C:\Users\linkin\AppData\Local\Programs\Python\Python37\lib\site-packages\flask\app.py", line 1813, in full_dispatch_request
    rv = self.dispatch_request()
  File "C:\Users\linkin\AppData\Local\Programs\Python\Python37\lib\site-packages\flask\app.py", line 1799, in dispatch_request
    return self.view_functions[rule.endpoint](**req.view_args)
  File "D:\CODE\FooProxy\APIserver\apiserver.py", line 30, in get_proxy
    data = db.select({'ip':'119.27.177.169','port':'80'})[1:]
  File "D:\CODE\FooProxy\Helper\dbhelper.py", line 125, in select
    raise e
  File "D:\CODE\FooProxy\Helper\dbhelper.py", line 118, in select
    data = list(data[0].values())
IndexError: list index out of range
