2018-10-08 21:58:06,416 (MainProcess pid:7388) line-1761  flask.app <log_exception> - [ERROR] : Exception on /proxy/anony/10 [GET]
Traceback (most recent call last):
  File "C:\Users\linkin\AppData\Local\Programs\Python\Python37\lib\site-packages\flask\app.py", line 2292, in wsgi_app
    response = self.full_dispatch_request()
  File "C:\Users\linkin\AppData\Local\Programs\Python\Python37\lib\site-packages\flask\app.py", line 1815, in full_dispatch_request
    rv = self.handle_user_exception(e)
  File "C:\Users\linkin\AppData\Local\Programs\Python\Python37\lib\site-packages\flask\app.py", line 1718, in handle_user_exception
    reraise(exc_type, exc_value, tb)
  File "C:\Users\linkin\AppData\Local\Programs\Python\Python37\lib\site-packages\flask\_compat.py", line 35, in reraise
    raise value
  File "C:\Users\linkin\AppData\Local\Programs\Python\Python37\lib\site-packages\flask\app.py", line 1813, in full_dispatch_request
    rv = self.dispatch_request()
  File "C:\Users\linkin\AppData\Local\Programs\Python\Python37\lib\site-packages\flask\app.py", line 1799, in dispatch_request
    return self.view_functions[rule.endpoint](**req.view_args)
  File "D:\CODE\FooProxy\APIserver\apiserver.py", line 37, in get_proxy
NameError: name 'data' is not defined
2018-10-08 21:58:09,749 (MainProcess pid:7388) line-1761  flask.app <log_exception> - [ERROR] : Exception on /proxy/anony [GET]
Traceback (most recent call last):
  File "C:\Users\linkin\AppData\Local\Programs\Python\Python37\lib\site-packages\flask\app.py", line 2292, in wsgi_app
    response = self.full_dispatch_request()
  File "C:\Users\linkin\AppData\Local\Programs\Python\Python37\lib\site-packages\flask\app.py", line 1815, in full_dispatch_request
    rv = self.handle_user_exception(e)
  File "C:\Users\linkin\AppData\Local\Programs\Python\Python37\lib\site-packages\flask\app.py", line 1718, in handle_user_exception
    reraise(exc_type, exc_value, tb)
  File "C:\Users\linkin\AppData\Local\Programs\Python\Python37\lib\site-packages\flask\_compat.py", line 35, in reraise
    raise value
  File "C:\Users\linkin\AppData\Local\Programs\Python\Python37\lib\site-packages\flask\app.py", line 1813, in full_dispatch_request
    rv = self.dispatch_request()
  File "C:\Users\linkin\AppData\Local\Programs\Python\Python37\lib\site-packages\flask\app.py", line 1799, in dispatch_request
    return self.view_functions[rule.endpoint](**req.view_args)
  File "D:\CODE\FooProxy\APIserver\apiserver.py", line 37, in get_proxy
NameError: name 'data' is not defined
2018-10-08 21:58:42,382 (MainProcess pid:7388) line-1761  flask.app <log_exception> - [ERROR] : Exception on /proxy/anony [GET]
Traceback (most recent call last):
  File "C:\Users\linkin\AppData\Local\Programs\Python\Python37\lib\site-packages\flask\app.py", line 2292, in wsgi_app
    response = self.full_dispatch_request()
  File "C:\Users\linkin\AppData\Local\Programs\Python\Python37\lib\site-packages\flask\app.py", line 1815, in full_dispatch_request
    rv = self.handle_user_exception(e)
  File "C:\Users\linkin\AppData\Local\Programs\Python\Python37\lib\site-packages\flask\app.py", line 1718, in handle_user_exception
    reraise(exc_type, exc_value, tb)
  File "C:\Users\linkin\AppData\Local\Programs\Python\Python37\lib\site-packages\flask\_compat.py", line 35, in reraise
    raise value
  File "C:\Users\linkin\AppData\Local\Programs\Python\Python37\lib\site-packages\flask\app.py", line 1813, in full_dispatch_request
    rv = self.dispatch_request()
  File "C:\Users\linkin\AppData\Local\Programs\Python\Python37\lib\site-packages\flask\app.py", line 1799, in dispatch_request
    return self.view_functions[rule.endpoint](**req.view_args)
  File "D:\CODE\FooProxy\APIserver\apiserver.py", line 37, in get_proxy
NameError: name 'data' is not defined
